Workbook
Name _Toc531375826: Assumptions!$A$1
Name Hourly_Rate: 'Equipment Breakdown'!#REF!
Name Hourly_Rate: 'Saas Costs'!#REF!
Name Hourly_Rate: 'Service Costs'!#REF!
Name Hourly_Rate: 'Summation Costs'!#REF!
Name Hourly_Rate: 'Travel Costs'!#REF!
Name Hourly_Rate: #REF!
Name Parameters_AdditionalUsers: Parameters!$B$6
Name Parameters_BidirectionalInterfaceCount: Parameters!$B$41
Name Parameters_CheckRecognition_Active: Parameters!$B$13
Name Parameters_CheckRecognition_Scans: Parameters!$E$13
Name Parameters_CheckValidation_Active: Parameters!$B$14
Name Parameters_CreditIntegration_Active: Parameters!$B$22
Name Parameters_CreditIntegration_New: Parameters!$C$22
Name Parameters_Departments: Parameters!$B$7
Name Parameters_Edition: Parameters!$B$4
Name Parameters_ImageCashLetter_Active: Parameters!$B$15
Name Parameters_ImageCashLetter_New: Parameters!$C$15
Name Parameters_LengthOfProject: Parameters!$B$8
Name Parameters_NamedOrConcurrent: Parameters!$B$5
Name Parameters_OnCallSupport: Parameters!$B$10
Name Parameters_OnlineForm_Estimate: Parameters!$C$68
Name Parameters_OnlineFormCount: Parameters!$B$68
Name Parameters_OnlineFormWithWorkflow_Estimate: Parameters!$C$73
Name Parameters_OnlineFormWithWorkflowCount: Parameters!$B$73
Name Parameters_RevenueSubmission_Active: Parameters!$B$16
Name Parameters_RevenueSubmission_Submitters: Parameters!$E$16
Name Parameters_ShowPerDiemCosts: Parameters!#REF!
Name Parameters_TellerOnline_Active: Parameters!$B$18
Name Parameters_TellerOnline_Interfaces: Parameters!$D$41
Name Parameters_TellerOnline_Interfaces_New: Parameters!$E$41
Name Parameters_TellerOnline_Volume: Parameters!$E$18
Name Parameters_TravelZone: Parameters!$B$9
Name Parameters_Workflow_Active: Parameters!#REF!
Name Parameters_WorkflowSubmission_Active: Parameters!$B$17
Name Parameters_WorkflowSubmission_Workflows: Parameters!$E$17
Name SaaSUploadRate: '[1]Service Breakdown'!#REF!
Name SaaSUploadRate: 'Equipment Breakdown'!#REF!
Name SaaSUploadRate: 'Saas Costs'!#REF!
Name SaaSUploadRate: 'Service Costs'!#REF!
Name SaaSUploadRate: 'Summation Costs'!#REF!
Name SaaSUploadRate: 'Travel Costs'!#REF!
Name SaaSUploadRate: #REF!
Name Services_BiDirectionalExistingImpl: 'Variables-Services'!$D$54
Name Services_BiDirectionalExistingPlanning: 'Variables-Services'!$D$23
Name Services_BiDirectionalNewImpl: 'Variables-Services'!$D$55
Name Services_BiDirectionalNewPlanning: 'Variables-Services'!$D$24
Name Services_HourlyRate: 'Variables-Services'!$C$3
Name Services_PaymentImportExisting: 'Variables-Services'!$D$25
Name Services_PaymentImportExistingImpl: 'Variables-Services'!$D$56
Name Services_PaymentImportNew: 'Variables-Services'!$D$26
Name Services_PaymentImportNewImpl: 'Variables-Services'!$D$57
Name Software_BiDirectional: 'Variables-Software'!$C$55
Name Software_ImageCashLetter_Minimum: 'Variables-Software'!$C$19
Name Software_ImageCashLetter_PercentPricing: 'Variables-Software'!$C$18
Name Software_OnlineInterface: 'Variables-Software'!$C$56
Name Software_PaymentImport: 'Variables-Software'!$C$57
Name Trip_Day_Cost: 'Equipment Breakdown'!#REF!
Name Trip_Day_Cost: 'Saas Costs'!#REF!
Name Trip_Day_Cost: 'Service Costs'!#REF!

Sheet Parameters
A1: Category | G1: Data | H1: Notes | J1: Version | K1: 11 | L1: 45588
A2: Information
A3: Name of Agency | G3: TELLER CLIENT, STATE
A4: Teller Standard or Basic | B4: S | J4: Complexity Quotient
A5: Named or Concurrent Users | B5: N
A6: Number of Additional Users | B6: 1 | J6: Factor | K6: Computer | L6: Override
A7: Departments to Implement | B7: 2
A8: Length of Project | B8: 9 | J8: Complex Value | K8: =IF(K10<20,1,IF(K10<35, 2,3)) -> 1 | L8: =K8 -> 1
A9: Travel Zone (1-4) | B9: 2 | J9: (1=Low) (1-3)
A10: 24/7 on call support | B10: N | J10: Total | K10: =SUM(K12:K23) -> 17
A12: Applications | B12: Active | C12: New | E12: Volume | J12: Users | K12: =SUM(B6+5) -> 6
A13: Check Recognition/Bulk Scanning | B13: Y | D13: Scans: | E13: 75000 | J13: ICL | K13: =IF(B15="Y", 1, 0) -> 1
A14: Check Validation | B14: N | H14: NOTE: Requires Check Recognition | I14: =B15&C15 -> YY
A15: Image Cash Letter | B15: Y | C15: Y | G15: ???? | J15: Rev Sub | K15: =IF(B16="Y", 1, 0) -> 1
A16: Revenue Submission | B16: Y | D16: Submitters: | E16: 15
A17: Workflow Submission | B17: N | D17: Workflows: | E17: 2 | H17: NOTE: Choose Revenue or Workflow Submission | J17: Online WF | K17: =IF(B18="Y", 1, 0) -> 1
A18: Online Customer Portal | B18: Y | D18: Transactions: | E18: 50000 | G18: NOTE SCOPE | J18: Bi-Dir | K18: =+B41*2 -> 6
J19: Bi-Dir (Online) | K19: =D41 -> 0
J20: Pay Imp | K20: =B61 -> 2
A21: Integrations - Bi-Directional | B21: Active | C21: New | D21: Online | E21: Online - New | J21: Misc | K21: 0
A22: Credit Processor | B22: Y | C22: N | G22: ???? | I22: =B22&C22 -> YN
A23: Financials | B23: Y | C23: N | G23: ???? | I23: =B23&C23 -> YN
A24: Financials A/R | B24: Y | C24: N | D24: N | E24: N | G24: ???? | I24: =B24&C24 -> YN
A25: Bi-Directional - | B25: Y | C25: N | D25: N | E25: N | G25: ???? | I25: =B25&C25 -> YN
A26: Bi-Directional - | B26: Y | C26: Y | D26: N | E26: Y | G26: ???? | I26: =B26&C26 -> YY
A27: Bi-Directional - | B27: N | C27: N | D27: N | E27: N | G27: Test 3 | I27: =B27&C27 -> NN
A28: Bi-Directional - | B28: N | C28: N | D28: N | E28: N | G28: Test 4 | I28: =B28&C28 -> NN
A29: Bi-Directional - | B29: N | C29: N | D29: N | E29: N | G29: Test 5 | I29: =B29&C29 -> NN
A30: Bi-Directional - | B30: N | C30: N | D30: N | E30: N | G30: Test 6 | I30: =B30&C30 -> NN
A31: Bi-Directional - | B31: N | C31: N | D31: N | E31: N | G31: Test 7 | I31: =B31&C31 -> NN
A32: Bi-Directional - | B32: N | C32: N | D32: N | E32: N | G32: Test 8 | I32: =B32&C32 -> NN
A33: Bi-Directional - | B33: N | C33: N | D33: N | E33: N | G33: Test 9 | I33: =B33&C33 -> NN
A34: Bi-Directional - | B34: N | C34: N | D34: N | E34: N | G34: Test 10 | I34: =B34&C34 -> NN
A35: Bi-Directional - | B35: N | C35: N | D35: N | E35: N | G35: Test 11 | I35: =B35&C35 -> NN
... A39: Bi-Directional - | B39: N | C39: N | D39: N | E39: N | G39: Test 15 | I39: =B39&C39 -> NN
A41: Bi-Directional Interface Count | B41: =COUNTIF(B24:B39,"Y") -> 3 | C41: =COUNTIF(C24:C39,"Y") -> 1 | D41: =COUNTIF(D24:D39,"Y") -> 0 | E41: =COUNTIF(E24:E39,"Y") -> 1
A44: Integrations - Payment Import | B44: Active | C44: New
A45: Payment Import - | B45: Y | C45: N | G45: ???? | I45: =B45&C45 -> YN
A46: Payment Import - | B46: Y | C46: N | G46: ???? | I46: =B46&C46 -> YN
A47: Payment Import - | B47: N | C47: N | G47: Import Test 3 | I47: =B47&C47 -> NN
...

Sheet Notes for Approver
A1: Version | B1: Version Personnel | C1: ="Version Notes for - "&Parameters!G3 -> Version Notes for - TELLER CLIENT, STATE | D1: Version Date
A3: V1 | B3: Scott
A6: V2 | B6: Josh
A8: V3 | B8: Scott
A10: V4 | B10: Josh
A12: V5 | B12: Scott

Sheet Summation Costs
A1: =Parameters!G3 -> TELLER CLIENT, STATE
A2: Investment Analysis
A4: Year | B4: Services | C4: Estimated Travel | D4: Equipment | E4: SaaS Fees | G4: Total Cost
A6: 1 | B6: =SUM('Service Costs'!$D49+'Service Costs'!$H49+'Service Costs'!$L32+'Service Costs'!$L8+'Service Costs'!$L34) -> 153180 | C6: ='Travel Costs'!$N13 -> 11370 | D6: ='Equipment Breakdown'!$F22 -> 0 | E6: ='Saas Costs'!$C60 -> 86094 | G6: =SUM(B6+C6+D6+E6) -> 250644
A7: 2 | B7: 0 | C7: 0 | D7: 0 | E7: =E6*'Variables-Software'!$C61 -> 89537.76 | G7: =SUM(B7+C7+D7+E7) -> 89537.76
A8: 3 | B8: 0 | C8: 0 | D8: 0 | E8: =E7*'Variables-Software'!$C62 -> 93119.27 | G8: =SUM(B8+C8+D8+E8) -> 93119.27
A9: 4 | B9: 0 | C9: 0 | D9: 0 | E9: =E8*'Variables-Software'!$C63 -> 96844.041 | G9: =SUM(B9+C9+D9+E9) -> 96844.041
A10: 5 | B10: 0 | C10: 0 | D10: 0 | E10: =E9*'Variables-Software'!$C64 -> 100717.8 | G10: =SUM(B10+C10+D10+E10) -> 100717.8
A11: 5 Year Cost | B11: =SUM(B6:B10) -> 153180 | C11: =SUM(C6:C10) -> 11370 | D11: =SUM(D6:D10) -> 0 | E11: =SUM(E6:E10) -> 466312.87 | G11: =SUM(G6:G10) -> 630862.87
A12: Sales Tax not included
A13: 6 | B13: 0 | C13: 0 | D13: 0 | E13: =E10*'Variables-Software'!$C65 -> 104746.51 | G13: =SUM(B13+C13+D13+E13) -> 104746.51
A14: 7 | B14: 0 | C14: 0 | D14: 0 | E14: =E13*'Variables-Software'!$C66 -> 108936.38 | G14: =SUM(B14+C14+D14+E14) -> 108936.38
A15: 8 | B15: 0 | C15: 0 | D15: 0 | E15: =E14*'Variables-Software'!$C67 -> 113293.83 | G15: =SUM(B15+C15+D15+E15) -> 113293.83
A16: 9 | B16: 0 | C16: 0 | D16: 0 | E16: =E15*'Variables-Software'!$C68 -> 117825.58 | G16: =SUM(B16+C16+D16+E16) -> 117825.58
A17: 10 | B17: 0 | C17: 0 | D17: 0 | E17: =E16*'Variables-Software'!$C69 -> 122538.61 | G17: =SUM(B17+C17+D17+E17) -> 122538.61
A18: 10 year Investment | E18: =SUM(E11:E17) -> 1033653.8 | G18: =SUM(G11:G17) -> 1198203.8
A19: Sales Tax not included
E21: =SUM(E6:E17)-E11 -> 1033653.8
A23: Service = Services+Travel Time costs

Sheet Saas Costs
A1: ="SaaS Calculations - "&Parameters!G3 -> SaaS Calculations - TELLER CLIENT, STATE
B3: Estimated Amount | C3: Pricing Amount | E3: Notes
A5: SaaS | B5: Amounts
A6: Teller Plan | B6: =IF(Parameters_Edition="S",'Variables-Software'!$C3,'Variables-Software'!C4) -> 2950 | C6: =B6 -> 2950
A7: Additional Named Users | B7: =IF(OR(Parameters_AdditionalUsers<1,Parameters_NamedOrConcurrent<>"N"),0,IF(Parameters_AdditionalUsers<45,('Variables-Software'!$C5*Parameters_AdditionalUsers),('Variables-Software'!$C6*Parameters_AdditionalUsers))) -> 60 | C7: =B7 -> 60 | E7: Base: 5
A8: Additional Concurrent Users | B8: =IF(OR(Parameters_AdditionalUsers<1,Parameters_NamedOrConcurrent="N"),0,IF(Parameters_AdditionalUsers<45,('Variables-Software'!$C5*Parameters_AdditionalUsers),('Variables-Software'!$C6*Parameters_AdditionalUsers)) * 3) -> 0 | C8: =B8 -> 0 | E8: Base: 3
C9: =B9
A10: Applications | C10: =B10
A11: =IF(Parameters_CheckRecognition_Active="Y",Parameters!A13,"") -> Check Recognition/Bulk Scanning | B11: =IF(Parameters_CheckRecognition_Active="Y",((LOOKUP(Parameters_CheckRecognition_Scans,'Variables-Software'!$B9:B16, 'Variables-Software'!$C9:C16))),0) -> 1030 | C11: =B11 -> 1030
A12: =IF(Parameters_CheckValidation_Active="Y",Parameters!A14,"") | B12: =IF(Parameters_CheckValidation_Active="Y", B11, 0) -> 0 | C12: =B12 -> 0
A13: =IF(Parameters_ImageCashLetter_Active="Y",Parameters!A15,"") -> Image Cash Letter | B13: =IF(Parameters_ImageCashLetter_Active="Y",MAX(C11 * Software_ImageCashLetter_PercentPricing, Software_ImageCashLetter_Minimum), 0) -> 669.5 | C13: =B13 -> 669.5
A14: =IF(Parameters_RevenueSubmission_Active="Y",Parameters!A16,"") -> Revenue Submission | B14: =IF(Parameters_RevenueSubmission_Active="Y",((LOOKUP(Parameters_RevenueSubmission_Submitters,'Variables-Software'!$B21:B24, 'Variables-Software'!$C21:C24))),0) -> 570 | C14: =B14 -> 570
A15: =IF(Parameters_WorkflowSubmission_Active="Y",Parameters!A17,"") | B15: =IF(Parameters_WorkflowSubmission_Active="Y",((LOOKUP(Parameters_WorkflowSubmission_Workflows,'Variables-Software'!$B26:B30, 'Variables-Software'!$C26:C30))),0) -> 0 | C15: =B15 -> 0
A16: =IF(Parameters_TellerOnline_Active="Y",Parameters!A18,"") -> Online Customer Portal | B16: =IF(Parameters_TellerOnline_Active="Y",((LOOKUP(Parameters_TellerOnline_Volume,'Variables-Software'!$B32:B44, 'Variables-Software'!$C32:C44)))+(Software_OnlineInterface*Parameters_TellerOnline_Interfaces),0) -> 700 | C16: =B16 -> 700
A17: =IF(Parameters_OnlineFormCount > 0, " Online Forms", "") | B17: =IF(Parameters_OnlineFormCount>0,LOOKUP(Parameters_OnlineFormCount,'Variables-Software'!B47:B52,'Variables-Software'!C47:C52), 0) -> 0 | C17: =B17 -> 0
A18: =IF(Parameters_OnlineFormWithWorkflowCount > 0, " Online Forms with Workflow", "") | B18: =IF(Parameters_OnlineFormWithWorkflowCount>0,LOOKUP(Parameters_OnlineFormWithWorkflowCount,'Variables-Software'!B47:B52,'Variables-Software'!C47:C52) * 2, 0) -> 0 | C18: =B18 -> 0
A20: =IF(Parameters!B24="Y", Parameters!A24&" - "&Parameters!G24, "") -> Financials A/R - ???? | B20: =IF(Parameters!B24="Y",Software_BiDirectional,0) -> 285 | C20: =B20 -> 285
A21: =IF(Parameters!B25="Y", Parameters!A25&" - "&Parameters!G25, "") -> Bi-Directional - - ???? | B21: =IF(Parameters!B25="Y",Software_BiDirectional,0) -> 285 | C21: =B21 -> 285
A22: =IF(Parameters!B26="Y", Parameters!A26&" - "&Parameters!G26, "") -> Bi-Directional - - ???? | B22: =IF(Parameters!B26="Y",Software_BiDirectional,0) -> 285 | C22: =B22 -> 285
A23: =IF(Parameters!B27="Y", Parameters!A27&" - "&Parameters!G27, "") | B23: =IF(Parameters!B27="Y",Software_BiDirectional,0) -> 0 | C23: =B23 -> 0
A24: =IF(Parameters!B28="Y", Parameters!A28&" - "&Parameters!G28, "") | B24: =IF(Parameters!B28="Y",Software_BiDirectional,0) -> 0 | C24: =B24 -> 0
A25: =IF(Parameters!B29="Y", Parameters!A29&" - "&Parameters!G29, "") | B25: =IF(Parameters!B29="Y",Software_BiDirectional,0) -> 0 | C25: =B25 -> 0
A26: =IF(Parameters!B30="Y", Parameters!A30&" - "&Parameters!G30, "") | B26: =IF(Parameters!B30="Y",Software_BiDirectional,0) -> 0 | C26: =B26 -> 0
A27: =IF(Parameters!B31="Y", Parameters!A31&" - "&Parameters!G31, "") | B27: =IF(Parameters!B31="Y",Software_BiDirectional,0) -> 0 | C27: =B27 -> 0
A28: =IF(Parameters!B32="Y", Parameters!A32&" - "&Parameters!G32, "") | B28: =IF(Parameters!B32="Y",Software_BiDirectional,0) -> 0 | C28: =B28 -> 0
A29: =IF(Parameters!B33="Y", Parameters!A33&" - "&Parameters!G33, "") | B29: =IF(Parameters!B33="Y",Software_BiDirectional,0) -> 0 | C29: =B29 -> 0
A30: =IF(Parameters!B34="Y", Parameters!A34&" - "&Parameters!G34, "") | B30: =IF(Parameters!B34="Y",Software_BiDirectional,0) -> 0 | C30: =B30 -> 0
A31: =IF(Parameters!B35="Y", Parameters!A35&" - "&Parameters!G35, "") | B31: =IF(Parameters!B35="Y",Software_BiDirectional,0) -> 0 | C31: =B31 -> 0
... A35: =IF(Parameters!B39="Y", Parameters!A39&" - "&Parameters!G39, "") | B35: =IF(Parameters!B39="Y",Software_BiDirectional,0) -> 0 | C35: =B35 -> 0
A37: =IF(Parameters!B45="Y", Parameters!A45&Parameters!G45, "") -> Payment Import - ???? | B37: =IF(Parameters!B45="Y",Software_PaymentImport,0) -> 170 | C37: =B37 -> 170
A38: =IF(Parameters!B46="Y", Parameters!A46&Parameters!G46, "") -> Payment Import - ???? | B38: =IF(Parameters!B46="Y",Software_PaymentImport,0) -> 170 | C38: =B38 -> 170
A39: =IF(Parameters!B47="Y", Parameters!A47&Parameters!G47, "") | B39: =IF(Parameters!B47="Y",Software_PaymentImport,0) -> 0 | C39: =B39 -> 0
A40: =IF(Parameters!B48="Y", Parameters!A48&Parameters!G48, "") | B40: =IF(Parameters!B48="Y",Software_PaymentImport,0) -> 0 | C40: =B40 -> 0
A41: =IF(Parameters!B49="Y", Parameters!A49&Parameters!G49, "") | B41: =IF(Parameters!B49="Y",Software_PaymentImport,0) -> 0 | C41: =B41 -> 0
A42: =IF(Parameters!B50="Y", Parameters!A50&Parameters!G50, "") | B42: =IF(Parameters!B50="Y",Software_PaymentImport,0) -> 0 | C42: =B42 -> 0
A43: =IF(Parameters!B51="Y", Parameters!A51&Parameters!G51, "") | B43: =IF(Parameters!B51="Y",Software_PaymentImport,0) -> 0 | C43: =B43 -> 0
A44: =IF(Parameters!B52="Y", Parameters!A52&Parameters!G52, "") | B44: =IF(Parameters!B52="Y",Software_PaymentImport,0) -> 0 | C44: =B44 -> 0
A45: =IF(Parameters!B53="Y", Parameters!A53&Parameters!G53, "") | B45: =IF(Parameters!B53="Y",Software_PaymentImport,0) -> 0 | C45: =B45 -> 0
A46: =IF(Parameters!B54="Y", Parameters!A54&Parameters!G54, "") | B46: =IF(Parameters!B54="Y",Software_PaymentImport,0) -> 0 | C46: =B46 -> 0
A47: =IF(Parameters!B55="Y", Parameters!A55&Parameters!G55, "") | B47: =IF(Parameters!B55="Y",Software_PaymentImport,0) -> 0 | C47: =B47 -> 0
...

Sheet Service Costs
A1: ="Service Calculations - "&Parameters!G3 -> Service Calculations - TELLER CLIENT, STATE
B3: Estimated Hours | C3: Pricing Hours | D3: Services Costs | F3: Estimated Hours | G3: Pricing Hours | H3: Services Costs | J3: Estimated Hours | K3: Pricing Hours | L3: Standard Services Costs
A5: Service Tasks | B5: Planning | F5: Implementation | J5: Project Management | Q5: Role | R5: Hours
A6: Implementation Plan-Basic-Setup | B6: =IF(Parameters_Edition="S",'Variables-Services'!D8,'Variables-Services'!D9) -> 56 | C6: =B6 -> 56 | D6: =IF(C6>0,(C6*Services_HourlyRate),0) -> 12880 | F6: ='Variables-Services'!D36 -> 16 | G6: =F6 -> 16 | H6: =IF(G6>0,(G6*Services_HourlyRate),0) -> 3680 | J6: =SUM(Parameters!$B8*'Variables-Services'!$D69) -> 90 | K6: =J6 -> 90 | L6: =IF(K6>0,(K6*Services_HourlyRate),0) -> 20700 | Q6: Configurator Hours | R6: ='Hours By Role'!C45 -> #REF!
A7: Teller Setup | C7: =B7 -> 0 | D7: =IF(C7>0,(C7*Services_HourlyRate),0) -> 0 | F7: ='Variables-Services'!D37*Parameters_Departments -> 32 | G7: =F7 -> 32 | H7: =IF(G7>0,(G7*Services_HourlyRate),0) -> 7360 | L7: 0 | Q7: Technical Configuration Hours | R7: ='Hours By Role'!C46 -> #REF!
A8: Implementation Plan-Interfaces | J8: Total PM | L8: =L6+L7 -> 20700 | Q8: BA Hours | R8: ='Hours By Role'!C47 -> 66
A9: =IF(Parameters_ImageCashLetter_Active="Y",Parameters!A15&" - "&Parameters!G15,"""") -> Image Cash Letter - ???? | B9: =IF(Parameters_ImageCashLetter_Active="Y", 'Variables-Services'!D11,0) -> 8 | C9: =B9 -> 8 | D9: =IF(C9>0,(C9*Services_HourlyRate),0) -> 1840 | F9: =IF(Parameters!I14="NN",0,IF(Parameters!I14 ="NY",0,IF(Parameters!I14="YN", 'Variables-Services'!D39, IF(Parameters!I14="YY", 'Variables-Services'!D40,0)))) -> 12 | G9: =F9 -> 12 | H9: =IF(G9>0,(G9*Services_HourlyRate),0) -> 2760 | J9: Training | M9: Training Tasks | Q9: PM Hours | R9: ='Hours By Role'!C48 -> 63
A10: =IF(Parameters_RevenueSubmission_Active="Y", Parameters!A16, "") -> Revenue Submission | B10: =IF(Parameters_RevenueSubmission_Active="Y",((LOOKUP(Parameters_RevenueSubmission_Submitters,'Variables-Services'!$B12:B14, 'Variables-Services'!$D12:D14))),0) -> 12 | C10: =B10 -> 12 | D10: =IF(C10>0,(C10*Services_HourlyRate),0) -> 2760 | F10: =IF(Parameters_RevenueSubmission_Active="Y",((LOOKUP(Parameters_RevenueSubmission_Submitters,'Variables-Services'!$B41:B43, 'Variables-Services'!$D41:D43))),0) -> 24 | G10: =F10 -> 24 | H10: =IF(G10>0,(G10*Services_HourlyRate),0) -> 5520 | J10: =ROUNDUP(G49*'Variables-Services'!$D61,0) -> 32 | K10: =J10 -> 32 | L10: =IF(K10>0,(K10*Services_HourlyRate),0) -> 7360 | M10: UAT Support | Q10: PMA Hours | R10: ='Hours By Role'!C49 -> 27
A11: =IF(Parameters_TellerOnline_Active="Y", Parameters!A18, "") -> Online Customer Portal | B11: =IF(Parameters_TellerOnline_Active="Y",('Variables-Services'!D15+(Parameters_TellerOnline_Interfaces*'Variables-Services'!D16)),0) -> 8 | C11: =B11 -> 8 | D11: =IF(C11>0,(C11*Services_HourlyRate),0) -> 1840 | F11: =IF(Parameters_TellerOnline_Active="Y",('Variables-Services'!D44+(Parameters_TellerOnline_Interfaces*'Variables-Services'!D45)+(Parameters_TellerOnline_Interfaces_New*'Variables-Services'!D46)),0) -> 48 | G11: =F11 -> 48 | H11: =IF(G11>0,(G11*Services_HourlyRate),0) -> 11040 | J11: ='Variables-Services'!$D62*'Travel Costs'!$C9 -> 16 | K11: =J11 -> 16 | L11: =IF(K11>0,(K11*Services_HourlyRate),0) -> 3680 | M11: Prep - Training (Office) | Q11: Project Development Hours | R11: ='Hours By Role'!C50 -> 114
A12: =IF(Parameters_OnlineFormCount + Parameters_OnlineFormWithWorkflowCount > 0, " Online Forms", "") | B12: =(Parameters_OnlineForm_Estimate + Parameters_OnlineFormWithWorkflow_Estimate) * 0.2 -> 0 | C12: =B12 -> 0 | D12: =IF(C12>0,(C12*Services_HourlyRate),0) -> 0 | F12: =(Parameters_OnlineForm_Estimate + Parameters_OnlineFormWithWorkflow_Estimate) * 0.8 -> 0 | G12: =F12 -> 0 | H12: =IF(G12>0,(G12*Services_HourlyRate),0) -> 0 | J12: =IF(Parameters!K46>0, ('Variables-Services'!L13*Parameters!K46), 0) -> 0 | K12: =J12 -> 0 | L12: =IF(K12>0,(K12*'Variables-Services'!$C8),0) -> 0 | Q12: Product Development Hours | R12: ='Hours By Role'!C51 -> 0
A13: =IF(Parameters!B22="Y", Parameters!A22&" - "&Parameters!G22, "") -> Credit Processor - ???? | B13: =IF(Parameters!I22="NN",0,IF(Parameters!I22 ="NY",0,IF(Parameters!I22="YN", 'Variables-Services'!D17, IF(Parameters!I22="YY", 'Variables-Services'!D18,0)))) -> 4 | C13: =B13 -> 4 | D13: =IF(C13>0,(C13*Services_HourlyRate),0) -> 920 | F13: =IF(Parameters!I22="NN",0,IF(Parameters!I22 ="NY",0,IF(Parameters!I22="YN", 'Variables-Services'!D48, IF(Parameters!I22="YY", 'Variables-Services'!D49,0)))) -> 4 | G13: =F13 -> 4 | H13: =IF(G13>0,(G13*Services_HourlyRate),0) -> 920 | J13: 0 | K13: 0 | L13: =IF(K13>0,(K13*Services_HourlyRate),0) -> 0 | M13: Project Kickoff and Analysis | Q13: QA Hours | R13: ='Hours By Role'!C52 -> 18
A14: =IF(Parameters!B23="Y", Parameters!A23&" - "&Parameters!G23, "") -> Financials - ???? | B14: =IF(Parameters!I23="NN",0,IF(Parameters!I23 ="NY",0,IF(Parameters!I23="YN", 'Variables-Services'!D19, IF(Parameters!I23="YY", 'Variables-Services'!D20,0)))) -> 0 | C14: =B14 -> 0 | D14: =IF(C14>0,(C14*Services_HourlyRate),0) -> 0 | F14: =IF(Parameters!I23="NN",0,IF(Parameters!I23 ="NY",0,IF(Parameters!I23="YN", 'Variables-Services'!D50, IF(Parameters!I23="YY", 'Variables-Services'!D51,0)))) -> 0 | G14: =F14 -> 0 | H14: =IF(G14>0,(G14*Services_HourlyRate),0) -> 0 | J14: 0 | K14: 0 | L14: =IF(K14>0,(K14*Services_HourlyRate),0) -> 0 | M14: Interface Integration and Analysis | Q14: Trainer Hours | R14: ='Hours By Role'!C53 -> 47.6
A15: =IF(Parameters!B24="Y", Parameters!A24&" - "&Parameters!G24, "") -> Financials A/R - ???? | B15: =IF(Parameters!I24="NN",0,IF(Parameters!I24 ="NY",0,IF(Parameters!I24="YN", 'Variables-Services'!D21, IF(Parameters!I24="YY", 'Variables-Services'!D22,0)))) -> 8 | C15: =B15 -> 8 | D15: =IF(C15>0,(C15*Services_HourlyRate),0) -> 1840 | F15: =IF(Parameters!I24="NN",0,IF(Parameters!I24 ="NY",0,IF(Parameters!I24="YN", 'Variables-Services'!D52, IF(Parameters!I24="YY", 'Variables-Services'!D53,0)))) -> 20 | G15: =F15 -> 20 | H15: =IF(G15>0,(G15*Services_HourlyRate),0) -> 4600 | J15: =SUM('Travel Costs'!$C9*'Travel Costs'!$G9) -> 32 | K15: =J15 -> 32 | L15: =IF(K15>0,(K15*Services_HourlyRate),0) -> 7360 | M15: Training | Q15: Ops Hours | R15: ='Hours By Role'!C54 -> #REF!
A16: =IF(Parameters!B25="Y", Parameters!A25&Parameters!G25, "") -> Bi-Directional - ???? | B16: =IF(Parameters!I25="NN",0,IF(Parameters!I25 ="NY",0,IF(Parameters!I25="YN", Services_BiDirectionalExistingPlanning, IF(Parameters!I25="YY", Services_BiDirectionalNewPlanning,0)))) -> 8 | C16: =B16 -> 8 | D16: =IF(C16>0,(C16*Services_HourlyRate),0) -> 1840 | F16: =IF(Parameters!I25="NN",0,IF(Parameters!I25 ="NY",0,IF(Parameters!I25="YN", Services_BiDirectionalExistingImpl, IF(Parameters!I25="YY", Services_BiDirectionalNewImpl,0)))) -> 24 | G16: =F16 -> 24 | H16: =IF(G16>0,(G16*Services_HourlyRate),0) -> 5520 | J16: =SUM('Travel Costs'!$C10*'Travel Costs'!$G10) -> 16 | K16: =J16 -> 16 | L16: =IF(K16>0,(K16*Services_HourlyRate),0) -> 3680 | M16: Go Live Support | P16: Total: | R16: =SUM(R6:R15) -> #REF!
A17: =IF(Parameters!B26="Y", Parameters!A26&Parameters!G26, "") -> Bi-Directional - ???? | B17: =IF(Parameters!I26="NN",0,IF(Parameters!I26 ="NY",0,IF(Parameters!I26="YN", Services_BiDirectionalExistingPlanning, IF(Parameters!I26="YY", Services_BiDirectionalNewPlanning,0)))) -> 24 | C17: =B17 -> 24 | D17: =IF(C17>0,(C17*Services_HourlyRate),0) -> 5520 | F17: =IF(Parameters!I26="NN",0,IF(Parameters!I26 ="NY",0,IF(Parameters!I26="YN", Services_BiDirectionalExistingImpl, IF(Parameters!I26="YY", Services_BiDirectionalNewImpl,0)))) -> 100 | G17: =F17 -> 100 | H17: =IF(G17>0,(G17*Services_HourlyRate),0) -> 23000 | J17: =IF(Parameters!Q25="NN",0,IF(Parameters!Q25 ="NY",0,IF(Parameters!Q25="YN", 'Variables-Services'!L24, IF(Parameters!Q25="YY", 'Variables-Services'!#REF!,0)))) -> 0 | K17: =J17 -> 0 | L17: =IF(K17>0,(K17*Services_HourlyRate),0) -> 0
A18: =IF(Parameters!B27="Y", Parameters!A27&Parameters!G27, "") | B18: =IF(Parameters!I27="NN",0,IF(Parameters!I27 ="NY",0,IF(Parameters!I27="YN", Services_BiDirectionalExistingPlanning, IF(Parameters!I27="YY", Services_BiDirectionalNewPlanning,0)))) -> 0 | C18: =B18 -> 0 | D18: =IF(C18>0,(C18*Services_HourlyRate),0) -> 0 | F18: =IF(Parameters!I27="NN",0,IF(Parameters!I27 ="NY",0,IF(Parameters!I27="YN", Services_BiDirectionalExistingImpl, IF(Parameters!I27="YY", Services_BiDirectionalNewImpl,0)))) -> 0 | G18: =F18 -> 0 | H18: =IF(G18>0,(G18*Services_HourlyRate),0) -> 0 | J18: =IF(Parameters!P26="NN",0,IF(Parameters!P26 ="NY",0,IF(Parameters!P26="YN", 'Variables-Services'!#REF!, IF(Parameters!P26="YY", 'Variables-Services'!#REF!,0)))) -> 0 | K18: =L18/Services_HourlyRate -> 24 | L18: ='Travel Costs'!$I13 -> 5520 | M18: Travel Time
A19: =IF(Parameters!B28="Y", Parameters!A28&Parameters!G28, "") | B19: =IF(Parameters!I28="NN",0,IF(Parameters!I28 ="NY",0,IF(Parameters!I28="YN", Services_BiDirectionalExistingPlanning, IF(Parameters!I28="YY", Services_BiDirectionalNewPlanning,0)))) -> 0 | C19: =B19 -> 0 | D19: =IF(C19>0,(C19*Services_HourlyRate),0) -> 0 | F19: =IF(Parameters!I28="NN",0,IF(Parameters!I28 ="NY",0,IF(Parameters!I28="YN", Services_BiDirectionalExistingImpl, IF(Parameters!I28="YY", Services_BiDirectionalNewImpl,0)))) -> 0 | G19: =F19 -> 0 | H19: =IF(G19>0,(G19*Services_HourlyRate),0) -> 0 | J19: =IF(Parameters!P27="NN",0,IF(Parameters!P27 ="NY",0,IF(Parameters!P27="YN", 'Variables-Services'!#REF!, IF(Parameters!P27="YY", 'Variables-Services'!#REF!,0)))) -> 0 | K19: =J19 -> 0 | L19: =IF(K19>0,(K19*Services_HourlyRate),0) -> 0
A20: =IF(Parameters!B29="Y", Parameters!A29&Parameters!G29, "") | B20: =IF(Parameters!I29="NN",0,IF(Parameters!I29 ="NY",0,IF(Parameters!I29="YN", Services_BiDirectionalExistingPlanning, IF(Parameters!I29="YY", Services_BiDirectionalNewPlanning,0)))) -> 0 | C20: =B20 -> 0 | D20: =IF(C20>0,(C20*Services_HourlyRate),0) -> 0 | F20: =IF(Parameters!I29="NN",0,IF(Parameters!I29 ="NY",0,IF(Parameters!I29="YN", Services_BiDirectionalExistingImpl, IF(Parameters!I29="YY", Services_BiDirectionalNewImpl,0)))) -> 0 | G20: =F20 -> 0 | H20: =IF(G20>0,(G20*Services_HourlyRate),0) -> 0 | J20: =IF(Parameters!P28="NN",0,IF(Parameters!P28 ="NY",0,IF(Parameters!P28="YN", 'Variables-Services'!#REF!, IF(Parameters!P28="YY", 'Variables-Services'!#REF!,0)))) -> 0 | K20: =J20 -> 0 | L20: =IF(K20>0,(K20*Services_HourlyRate),0) -> 0
A21: =IF(Parameters!B30="Y", Parameters!A30&Parameters!G30, "") | B21: =IF(Parameters!I30="NN",0,IF(Parameters!I30 ="NY",0,IF(Parameters!I30="YN", Services_BiDirectionalExistingPlanning, IF(Parameters!I30="YY", Services_BiDirectionalNewPlanning,0)))) -> 0 | C21: =B21 -> 0 | D21: =IF(C21>0,(C21*Services_HourlyRate),0) -> 0 | F21: =IF(Parameters!I30="NN",0,IF(Parameters!I30 ="NY",0,IF(Parameters!I30="YN", Services_BiDirectionalExistingImpl, IF(Parameters!I30="YY", Services_BiDirectionalNewImpl,0)))) -> 0 | G21: =F21 -> 0 | H21: =IF(G21>0,(G21*Services_HourlyRate),0) -> 0 | J21: =IF(Parameters!Q43="NN",0,IF(Parameters!Q43 ="NY",0,IF(Parameters!Q43="YN", 'Variables-Services'!L25, IF(Parameters!Q43="YY", 'Variables-Services'!L26,0)))) -> 0 | K21: =J21 -> 0 | L21: =IF(K21>0,(K21*Services_HourlyRate),0) -> 0
A22: =IF(Parameters!B31="Y", Parameters!A31&Parameters!G31, "") | B22: =IF(Parameters!I31="NN",0,IF(Parameters!I31 ="NY",0,IF(Parameters!I31="YN", Services_BiDirectionalExistingPlanning, IF(Parameters!I31="YY", Services_BiDirectionalNewPlanning,0)))) -> 0 | C22: =B22 -> 0 | D22: =IF(C22>0,(C22*Services_HourlyRate),0) -> 0 | F22: =IF(Parameters!I31="NN",0,IF(Parameters!I31 ="NY",0,IF(Parameters!I31="YN", Services_BiDirectionalExistingImpl, IF(Parameters!I31="YY", Services_BiDirectionalNewImpl,0)))) -> 0 | G22: =F22 -> 0 | H22: =IF(G22>0,(G22*Services_HourlyRate),0) -> 0 | J22: =IF(Parameters!Q44="NN",0,IF(Parameters!Q44 ="NY",0,IF(Parameters!Q44="YN", 'Variables-Services'!#REF!, IF(Parameters!Q44="YY", 'Variables-Services'!#REF!,0)))) -> 0 | K22: =J22 -> 0 | L22: =IF(K22>0,(K22*Services_HourlyRate),0) -> 0
A23: =IF(Parameters!B32="Y", Parameters!A32&Parameters!G32, "") | B23: =IF(Parameters!I32="NN",0,IF(Parameters!I32 ="NY",0,IF(Parameters!I32="YN", Services_BiDirectionalExistingPlanning, IF(Parameters!I32="YY", Services_BiDirectionalNewPlanning,0)))) -> 0 | C23: =B23 -> 0 | D23: =IF(C23>0,(C23*Services_HourlyRate),0) -> 0 | F23: =IF(Parameters!I32="NN",0,IF(Parameters!I32 ="NY",0,IF(Parameters!I32="YN", Services_BiDirectionalExistingImpl, IF(Parameters!I32="YY", Services_BiDirectionalNewImpl,0)))) -> 0 | G23: =F23 -> 0 | H23: =IF(G23>0,(G23*Services_HourlyRate),0) -> 0 | J23: =IF(Parameters!Q45="NN",0,IF(Parameters!Q45 ="NY",0,IF(Parameters!Q45="YN", 'Variables-Services'!#REF!, IF(Parameters!Q45="YY", 'Variables-Services'!#REF!,0)))) -> 0 | K23: =J23 -> 0 | L23: =IF(K23>0,(K23*Services_HourlyRate),0) -> 0
A24: =IF(Parameters!B33="Y", Parameters!A33&Parameters!G33, "") | B24: =IF(Parameters!I33="NN",0,IF(Parameters!I33 ="NY",0,IF(Parameters!I33="YN", Services_BiDirectionalExistingPlanning, IF(Parameters!I33="YY", Services_BiDirectionalNewPlanning,0)))) -> 0 | C24: =B24 -> 0 | D24: =IF(C24>0,(C24*Services_HourlyRate),0) -> 0 | F24: =IF(Parameters!I33="NN",0,IF(Parameters!I33 ="NY",0,IF(Parameters!I33="YN", Services_BiDirectionalExistingImpl, IF(Parameters!I33="YY", Services_BiDirectionalNewImpl,0)))) -> 0 | G24: =F24 -> 0 | H24: =IF(G24>0,(G24*Services_HourlyRate),0) -> 0 | J24: =IF(Parameters!Q46="NN",0,IF(Parameters!Q46 ="NY",0,IF(Parameters!Q46="YN", 'Variables-Services'!#REF!, IF(Parameters!Q46="YY", 'Variables-Services'!#REF!,0)))) -> 0 | K24: =J24 -> 0 | L24: =IF(K24>0,(K24*Services_HourlyRate),0) -> 0
A25: =IF(Parameters!B34="Y", Parameters!A34&Parameters!G34, "") | B25: =IF(Parameters!I34="NN",0,IF(Parameters!I34 ="NY",0,IF(Parameters!I34="YN", Services_BiDirectionalExistingPlanning, IF(Parameters!I34="YY", Services_BiDirectionalNewPlanning,0)))) -> 0 | C25: =B25 -> 0 | D25: =IF(C25>0,(C25*Services_HourlyRate),0) -> 0 | F25: =IF(Parameters!I34="NN",0,IF(Parameters!I34 ="NY",0,IF(Parameters!I34="YN", Services_BiDirectionalExistingImpl, IF(Parameters!I34="YY", Services_BiDirectionalNewImpl,0)))) -> 0 | G25: =F25 -> 0 | H25: =IF(G25>0,(G25*Services_HourlyRate),0) -> 0 | J25: =IF(Parameters!Q47="NN",0,IF(Parameters!Q47 ="NY",0,IF(Parameters!Q47="YN", 'Variables-Services'!#REF!, IF(Parameters!Q47="YY", 'Variables-Services'!#REF!,0)))) -> 0 | K25: =J25 -> 0 | L25: =IF(K25>0,(K25*Services_HourlyRate),0) -> 0
A26: =IF(Parameters!B35="Y", Parameters!A35&Parameters!G35, "") | B26: =IF(Parameters!I35="NN",0,IF(Parameters!I35 ="NY",0,IF(Parameters!I35="YN", Services_BiDirectionalExistingPlanning, IF(Parameters!I35="YY", Services_BiDirectionalNewPlanning,0)))) -> 0 | C26: =B26 -> 0 | D26: =IF(C26>0,(C26*Services_HourlyRate),0) -> 0 | F26: =IF(Parameters!I35="NN",0,IF(Parameters!I35 ="NY",0,IF(Parameters!I35="YN", Services_BiDirectionalExistingImpl, IF(Parameters!I35="YY", Services_BiDirectionalNewImpl,0)))) -> 0 | G26: =F26 -> 0 | H26: =IF(G26>0,(G26*Services_HourlyRate),0) -> 0 | J26: =IF(Parameters!Q48="NN",0,IF(Parameters!Q48 ="NY",0,IF(Parameters!Q48="YN", 'Variables-Services'!#REF!, IF(Parameters!Q48="YY", 'Variables-Services'!#REF!,0)))) -> 0 | K26: =J26 -> 0 | L26: =IF(K26>0,(K26*Services_HourlyRate),0) -> 0
A27: =IF(Parameters!B36="Y", Parameters!A36&Parameters!G36, "") | B27: =IF(Parameters!I36="NN",0,IF(Parameters!I36 ="NY",0,IF(Parameters!I36="YN", Services_BiDirectionalExistingPlanning, IF(Parameters!I36="YY", Services_BiDirectionalNewPlanning,0)))) -> 0 | C27: =B27 -> 0 | D27: =IF(C27>0,(C27*Services_HourlyRate),0) -> 0 | F27: =IF(Parameters!I36="NN",0,IF(Parameters!I36 ="NY",0,IF(Parameters!I36="YN", Services_BiDirectionalExistingImpl, IF(Parameters!I36="YY", Services_BiDirectionalNewImpl,0)))) -> 0 | G27: =F27 -> 0 | H27: =IF(G27>0,(G27*Services_HourlyRate),0) -> 0 | J27: =IF(Parameters!Q49="NN",0,IF(Parameters!Q49 ="NY",0,IF(Parameters!Q49="YN", 'Variables-Services'!#REF!, IF(Parameters!Q49="YY", 'Variables-Services'!L33,0)))) -> 0 | K27: =J27 -> 0 | L27: =IF(K27>0,(K27*Services_HourlyRate),0) -> 0
A28: =IF(Parameters!B37="Y", Parameters!A37&Parameters!G37, "") | B28: =IF(Parameters!I37="NN",0,IF(Parameters!I37 ="NY",0,IF(Parameters!I37="YN", Services_BiDirectionalExistingPlanning, IF(Parameters!I37="YY", Services_BiDirectionalNewPlanning,0)))) -> 0 | C28: =B28 -> 0 | D28: =IF(C28>0,(C28*Services_HourlyRate),0) -> 0 | F28: =IF(Parameters!I37="NN",0,IF(Parameters!I37 ="NY",0,IF(Parameters!I37="YN", Services_BiDirectionalExistingImpl, IF(Parameters!I37="YY", Services_BiDirectionalNewImpl,0)))) -> 0 | G28: =F28 -> 0 | H28: =IF(G28>0,(G28*Services_HourlyRate),0) -> 0 | J28: =IF(Parameters!Q50="NN",0,IF(Parameters!Q50 ="NY",0,IF(Parameters!Q50="YN", 'Variables-Services'!L33, IF(Parameters!Q50="YY", 'Variables-Services'!L34,0)))) -> 0 | K28: =J28 -> 0 | L28: =IF(K28>0,(K28*Services_HourlyRate),0) -> 0
A29: =IF(Parameters!B38="Y", Parameters!A38&Parameters!G38, "") | B29: =IF(Parameters!I38="NN",0,IF(Parameters!I38 ="NY",0,IF(Parameters!I38="YN", Services_BiDirectionalExistingPlanning, IF(Parameters!I38="YY", Services_BiDirectionalNewPlanning,0)))) -> 0 | C29: =B29 -> 0 | D29: =IF(C29>0,(C29*Services_HourlyRate),0) -> 0 | F29: =IF(Parameters!I38="NN",0,IF(Parameters!I38 ="NY",0,IF(Parameters!I38="YN", Services_BiDirectionalExistingImpl, IF(Parameters!I38="YY", Services_BiDirectionalNewImpl,0)))) -> 0 | G29: =F29 -> 0 | H29: =IF(G29>0,(G29*Services_HourlyRate),0) -> 0
A30: =IF(Parameters!B39="Y", Parameters!A39&Parameters!G39, "") | B30: =IF(Parameters!I39="NN",0,IF(Parameters!I39 ="NY",0,IF(Parameters!I39="YN", Services_BiDirectionalExistingPlanning, IF(Parameters!I39="YY", Services_BiDirectionalNewPlanning,0)))) -> 0 | C30: =B30 -> 0 | D30: =IF(C30>0,(C30*Services_HourlyRate),0) -> 0 | F30: =IF(Parameters!I39="NN",0,IF(Parameters!I39 ="NY",0,IF(Parameters!I39="YN", Services_BiDirectionalExistingImpl, IF(Parameters!I39="YY", Services_BiDirectionalNewImpl,0)))) -> 0 | G30: =F30 -> 0 | H30: =IF(G30>0,(G30*Services_HourlyRate),0) -> 0
A31: =IF(Parameters!B45="Y", Parameters!A45&Parameters!G45, "") -> Payment Import - ???? | B31: =IF(Parameters!I45="NN",0,IF(Parameters!I45 ="NY",0,IF(Parameters!I45="YN", Services_PaymentImportExisting, IF(Parameters!I45="YY", Services_PaymentImportNew,0)))) -> 8 | C31: =B31 -> 8 | D31: =IF(C31>0,(C31*Services_HourlyRate),0) -> 1840 | F31: =IF(Parameters!I45="NN",0,IF(Parameters!I45 ="NY",0,IF(Parameters!I45="YN", Services_PaymentImportExistingImpl, IF(Parameters!I45="YY", Services_PaymentImportNewImpl,0)))) -> 16 | G31: =F31 -> 16 | H31: =IF(G31>0,(G31*Services_HourlyRate),0) -> 3680
A32: =IF(Parameters!B46="Y", Parameters!A46&Parameters!G46, "") -> Payment Import - ???? | B32: =IF(Parameters!I46="NN",0,IF(Parameters!I46 ="NY",0,IF(Parameters!I46="YN", Services_PaymentImportExisting, IF(Parameters!I46="YY", Services_PaymentImportNew,0)))) -> 8 | C32: =B32 -> 8 | D32: =IF(C32>0,(C32*Services_HourlyRate),0) -> 1840 | F32: =IF(Parameters!I46="NN",0,IF(Parameters!I46 ="NY",0,IF(Parameters!I46="YN", Services_PaymentImportExistingImpl, IF(Parameters!I46="YY", Services_PaymentImportNewImpl,0)))) -> 16 | G32: =F32 -> 16 | H32: =IF(G32>0,(G32*Services_HourlyRate),0) -> 3680 | J32: =SUM(J10:J29) -> 96 | K32: =SUM(K10:K29) -> 120 | L32: =SUM(L10:L29) -> 27600
A33: =IF(Parameters!B47="Y", Parameters!A47&Parameters!G47, "") | B33: =IF(Parameters!I47="NN",0,IF(Parameters!I47 ="NY",0,IF(Parameters!I47="YN", Services_PaymentImportExisting, IF(Parameters!I47="YY", Services_PaymentImportNew,0)))) -> 0 | C33: =B33 -> 0 | D33: =IF(C33>0,(C33*Services_HourlyRate),0) -> 0 | F33: =IF(Parameters!I47="NN",0,IF(Parameters!I47 ="NY",0,IF(Parameters!I47="YN", Services_PaymentImportExistingImpl, IF(Parameters!I47="YY", Services_PaymentImportNewImpl,0)))) -> 0 | G33: =F33 -> 0 | H33: =IF(G33>0,(G33*Services_HourlyRate),0) -> 0
A34: =IF(Parameters!B48="Y", Parameters!A48&Parameters!G48, "") | B34: =IF(Parameters!I48="NN",0,IF(Parameters!I48 ="NY",0,IF(Parameters!I48="YN", Services_PaymentImportExisting, IF(Parameters!I48="YY", Services_PaymentImportNew,0)))) -> 0 | C34: =B34 -> 0 | D34: =IF(C34>0,(C34*Services_HourlyRate),0) -> 0 | F34: =IF(Parameters!I48="NN",0,IF(Parameters!I48 ="NY",0,IF(Parameters!I48="YN", Services_PaymentImportExistingImpl, IF(Parameters!I48="YY", Services_PaymentImportNewImpl,0)))) -> 0 | G34: =F34 -> 0 | H34: =IF(G34>0,(G34*Services_HourlyRate),0) -> 0 | J34: SHI | K34: 0 | L34: =SUM((D49+H49+L32)*K34) -> 0
A35: =IF(Parameters!B49="Y", Parameters!A49&Parameters!G49, "") | B35: =IF(Parameters!I49="NN",0,IF(Parameters!I49 ="NY",0,IF(Parameters!I49="YN", Services_PaymentImportExisting, IF(Parameters!I49="YY", Services_PaymentImportNew,0)))) -> 0 | C35: =B35 -> 0 | D35: =IF(C35>0,(C35*Services_HourlyRate),0) -> 0 | F35: =IF(Parameters!I49="NN",0,IF(Parameters!I49 ="NY",0,IF(Parameters!I49="YN", Services_PaymentImportExistingImpl, IF(Parameters!I49="YY", Services_PaymentImportNewImpl,0)))) -> 0 | G35: =F35 -> 0 | H35: =IF(G35>0,(G35*Services_HourlyRate),0) -> 0
A36: =IF(Parameters!B50="Y", Parameters!A50&Parameters!G50, "") | B36: =IF(Parameters!I50="NN",0,IF(Parameters!I50 ="NY",0,IF(Parameters!I50="YN", Services_PaymentImportExisting, IF(Parameters!I50="YY", Services_PaymentImportNew,0)))) -> 0 | C36: =B36 -> 0 | D36: =IF(C36>0,(C36*Services_HourlyRate),0) -> 0 | F36: =IF(Parameters!I50="NN",0,IF(Parameters!I50 ="NY",0,IF(Parameters!I50="YN", Services_PaymentImportExistingImpl, IF(Parameters!I50="YY", Services_PaymentImportNewImpl,0)))) -> 0 | G36: =F36 -> 0 | H36: =IF(G36>0,(G36*Services_HourlyRate),0) -> 0
A37: =IF(Parameters!B51="Y", Parameters!A51&Parameters!G51, "") | B37: =IF(Parameters!I51="NN",0,IF(Parameters!I51 ="NY",0,IF(Parameters!I51="YN", Services_PaymentImportExisting, IF(Parameters!I51="YY", Services_PaymentImportNew,0)))) -> 0 | C37: =B37 -> 0 | D37: =IF(C37>0,(C37*Services_HourlyRate),0) -> 0 | F37: =IF(Parameters!I51="NN",0,IF(Parameters!I51 ="NY",0,IF(Parameters!I51="YN", Services_PaymentImportExistingImpl, IF(Parameters!I51="YY", Services_PaymentImportNewImpl,0)))) -> 0 | G37: =F37 -> 0 | H37: =IF(G37>0,(G37*Services_HourlyRate),0) -> 0
A38: =IF(Parameters!B52="Y", Parameters!A52&Parameters!G52, "") | B38: =IF(Parameters!I52="NN",0,IF(Parameters!I52 ="NY",0,IF(Parameters!I52="YN", Services_PaymentImportExisting, IF(Parameters!I52="YY", Services_PaymentImportNew,0)))) -> 0 | C38: =B38 -> 0 | D38: =IF(C38>0,(C38*Services_HourlyRate),0) -> 0 | F38: =IF(Parameters!I52="NN",0,IF(Parameters!I52 ="NY",0,IF(Parameters!I52="YN", Services_PaymentImportExistingImpl, IF(Parameters!I52="YY", Services_PaymentImportNewImpl,0)))) -> 0 | G38: =F38 -> 0 | H38: =IF(G38>0,(G38*Services_HourlyRate),0) -> 0
A39: =IF(Parameters!B53="Y", Parameters!A53&Parameters!G53, "") | B39: =IF(Parameters!I53="NN",0,IF(Parameters!I53 ="NY",0,IF(Parameters!I53="YN", Services_PaymentImportExisting, IF(Parameters!I53="YY", Services_PaymentImportNew,0)))) -> 0 | C39: =B39 -> 0 | D39: =IF(C39>0,(C39*Services_HourlyRate),0) -> 0 | F39: =IF(Parameters!I53="NN",0,IF(Parameters!I53 ="NY",0,IF(Parameters!I53="YN", Services_PaymentImportExistingImpl, IF(Parameters!I53="YY", Services_PaymentImportNewImpl,0)))) -> 0 | G39: =F39 -> 0 | H39: =IF(G39>0,(G39*Services_HourlyRate),0) -> 0
A40: =IF(Parameters!B54="Y", Parameters!A54&Parameters!G54, "") | B40: =IF(Parameters!I54="NN",0,IF(Parameters!I54 ="NY",0,IF(Parameters!I54="YN", Services_PaymentImportExisting, IF(Parameters!I54="YY", Services_PaymentImportNew,0)))) -> 0 | C40: =B40 -> 0 | D40: =IF(C40>0,(C40*Services_HourlyRate),0) -> 0 | F40: =IF(Parameters!I54="NN",0,IF(Parameters!I54 ="NY",0,IF(Parameters!I54="YN", Services_PaymentImportExistingImpl, IF(Parameters!I54="YY", Services_PaymentImportNewImpl,0)))) -> 0 | G40: =F40 -> 0 | H40: =IF(G40>0,(G40*Services_HourlyRate),0) -> 0
A41: =IF(Parameters!B55="Y", Parameters!A55&Parameters!G55, "") | B41: =IF(Parameters!I55="NN",0,IF(Parameters!I55 ="NY",0,IF(Parameters!I55="YN", Services_PaymentImportExisting, IF(Parameters!I55="YY", Services_PaymentImportNew,0)))) -> 0 | C41: =B41 -> 0 | D41: =IF(C41>0,(C41*Services_HourlyRate),0) -> 0 | F41: =IF(Parameters!I55="NN",0,IF(Parameters!I55 ="NY",0,IF(Parameters!I55="YN", Services_PaymentImportExistingImpl, IF(Parameters!I55="YY", Services_PaymentImportNewImpl,0)))) -> 0 | G41: =F41 -> 0 | H41: =IF(G41>0,(G41*Services_HourlyRate),0) -> 0
A42: =IF(Parameters!B56="Y", Parameters!A56&Parameters!G56, "") | B42: =IF(Parameters!I56="NN",0,IF(Parameters!I56 ="NY",0,IF(Parameters!I56="YN", Services_PaymentImportExisting, IF(Parameters!I56="YY", Services_PaymentImportNew,0)))) -> 0 | C42: =B42 -> 0 | D42: =IF(C42>0,(C42*Services_HourlyRate),0) -> 0 | F42: =IF(Parameters!I56="NN",0,IF(Parameters!I56 ="NY",0,IF(Parameters!I56="YN", Services_PaymentImportExistingImpl, IF(Parameters!I56="YY", Services_PaymentImportNewImpl,0)))) -> 0 | G42: =F42 -> 0 | H42: =IF(G42>0,(G42*Services_HourlyRate),0) -> 0
...

Sheet Hours By Role
B5: Configuration Planning | D5: Technical Configuration Planning | F5: Interface Planning | H5: Implemenation Configuration | J5: Implemenation Technical Configuration | L5: Implementation Development | N5: Implemenation Product Work | P5: Training Preparation | R5: Training | T5: UAT/Go-Live Project | V5: UAT/Go-Live Product | X5: Project Management | Z5: Travel
A6: Implementation Plan-Basic-Setup | B6: Implementation Plan-Basic-Setup | C6: ='Service Costs'!C6 -> 56 | H6: Implementation Plan-Basic-Setup | I6: ='Service Costs'!G6 -> 16 | P6: Prep - Training (Office) | Q6: ='Service Costs'!K11 -> 16 | R6: Training | S6: ='Service Costs'!K15 -> 32 | T6: UAT Support | U6: ='Service Costs'!K10 -> 32 | X6: Project Management | Y6: ='Service Costs'!K6 -> 90 | Z6: Travel Time | AA6: ='Service Costs'!K18 -> 24
A7: Teller Setup | B7: Teller Setup | C7: ='Service Costs'!C7 -> 0 | H7: Teller Setup | I7: ='Service Costs'!G7 -> 32 | T7: Go Live Support | U7: ='Service Costs'!K16 -> 16
A8: Implementation Plan-Interfaces
A9: =IF(Parameters_CheckRecognition_Active="Y", Parameters!A13, "") -> Check Recognition/Bulk Scanning | B9: =IF(Parameters_CheckRecognition_Active="Y", Parameters!A13, "") -> Check Recognition/Bulk Scanning | C9: ='Service Costs'!#REF! -> #REF! | J9: =IF(Parameters_CheckRecognition_Active="Y", Parameters!A13, "") -> Check Recognition/Bulk Scanning
A10: =IF(Parameters_ImageCashLetter_Active="Y",Parameters!A15&" - "&Parameters!G15,"""") -> Image Cash Letter - ???? | F10: =IF(Parameters_ImageCashLetter_Active="Y",Parameters!A15&" - "&Parameters!G15,"""") -> Image Cash Letter - ???? | G10: ='Service Costs'!C9 -> 8 | J10: =IF(Parameters!I14="NN","",IF(Parameters!I14 ="NY","",IF(Parameters!I14="YN", Parameters!A15&" - "&Parameters!G15, IF(Parameters!I14="YY", "","")))) | K10: =IF(Parameters!I14="NN",0,IF(Parameters!I14 ="NY",0,IF(Parameters!I14="YN", 'Service Costs'!G9, IF(Parameters!I14="YY", 0,0)))) -> 0 | L10: =IF(Parameters!I14="NN","",IF(Parameters!I14 ="NY","",IF(Parameters!I14="YN", "", IF(Parameters!I14="YY", Parameters!A15&" - "&Parameters!G15,"")))) -> Image Cash Letter - ???? | M10: =IF(Parameters!I14="NN",0,IF(Parameters!I14 ="NY",0,IF(Parameters!I14="YN", 0, IF(Parameters!I14="YY", 'Service Costs'!G9,0)))) -> 12
A11: =IF(Parameters_RevenueSubmission_Active="Y", Parameters!A16, "") -> Revenue Submission | B11: =IF(Parameters_RevenueSubmission_Active="Y", Parameters!A16, "") -> Revenue Submission | C11: ='Service Costs'!C10 -> 12 | H11: =IF(Parameters_RevenueSubmission_Active="Y", Parameters!A16, "") -> Revenue Submission | I11: ='Service Costs'!G10 -> 24
A12: =IF(Parameters_TellerOnline_Active="Y", Parameters!A18, "") -> Online Customer Portal | B12: =IF(Parameters_TellerOnline_Active="Y", Parameters!A18, "") -> Online Customer Portal | C12: ='Service Costs'!C11 -> 8 | J12: =IF(Parameters_TellerOnline_Active="Y", Parameters!A18, "") -> Online Customer Portal | K12: ='Service Costs'!G11 -> 48
J13: =IF(Parameters!#REF!="Y", Parameters!#REF!, "") -> #REF! | K13: ='Service Costs'!#REF! -> #REF!
A14: =IF(Parameters!B22="Y", Parameters!A22&" - "&Parameters!G22, "") -> Credit Processor - ???? | F14: =IF(Parameters!B22="Y", Parameters!A22&" - "&Parameters!G22, "") -> Credit Processor - ???? | G14: ='Service Costs'!C13 -> 4 | L14: =IF(Parameters!B22="Y", Parameters!A22&" - "&Parameters!G22, "") -> Credit Processor - ???? | M14: ='Service Costs'!G13 -> 4
A15: =IF(Parameters!B23="Y", Parameters!A23&" - "&Parameters!G23, "") -> Financials - ???? | D15: =IF(Parameters!I23="NN","",IF(Parameters!I23 ="NY","",IF(Parameters!I23="YN", Parameters!A23&" - "&Parameters!G23, IF(Parameters!I23="YY", "","")))) -> Financials - ???? | E15: =IF(Parameters!I23="NN",0,IF(Parameters!I23 ="NY",0,IF(Parameters!I23="YN", 'Service Costs'!C14, IF(Parameters!I23="YY", 0,0)))) -> 0 | F15: =IF(Parameters!I23="NN","",IF(Parameters!I23 ="NY","",IF(Parameters!I23="YN", "", IF(Parameters!I23="YY", Parameters!A23&" - "&Parameters!G23,"")))) | G15: =IF(Parameters!I23="NN",0,IF(Parameters!I23 ="NY",0,IF(Parameters!I23="YN", 0, IF(Parameters!I23="YY", 'Service Costs'!C14,0)))) -> 0 | J15: =IF(Parameters!I23="NN","",IF(Parameters!I23 ="NY","",IF(Parameters!I23="YN", Parameters!A23&" - "&Parameters!G23, IF(Parameters!I23="YY", "","")))) -> Financials - ???? | K15: =IF(Parameters!I23="NN",0,IF(Parameters!I23 ="NY",0,IF(Parameters!I23="YN", 'Service Costs'!G14, IF(Parameters!I23="YY", 0,0)))) -> 0 | L15: =IF(Parameters!I23="NN","",IF(Parameters!I23 ="NY","",IF(Parameters!I23="YN", "", IF(Parameters!I23="YY", Parameters!A23&" - "&Parameters!G23,"")))) | M15: =IF(Parameters!I23="NN",0,IF(Parameters!I23 ="NY",0,IF(Parameters!I23="YN", 0, IF(Parameters!I23="YY", 'Service Costs'!G14,0)))) -> 0
A16: =IF(Parameters!B24="Y", Parameters!A24&" - "&Parameters!G24, "") -> Financials A/R - ???? | D16: =IF(Parameters!I24="NN","",IF(Parameters!I24 ="NY","",IF(Parameters!I24="YN", Parameters!A24&" - "&Parameters!G24, IF(Parameters!I24="YY", "","")))) -> Financials A/R - ???? | E16: =IF(Parameters!I24="NN",0,IF(Parameters!I24 ="NY",0,IF(Parameters!I24="YN", 'Service Costs'!C15, IF(Parameters!I24="YY", 0,0)))) -> 8 | F16: =IF(Parameters!I24="NN","",IF(Parameters!I24 ="NY","",IF(Parameters!I24="YN", "", IF(Parameters!I24="YY", Parameters!A24&" - "&Parameters!G24,"")))) | G16: =IF(Parameters!I24="NN",0,IF(Parameters!I24 ="NY",0,IF(Parameters!I24="YN", 0, IF(Parameters!I24="YY", 'Service Costs'!C15,0)))) -> 0 | J16: =IF(Parameters!I24="NN","",IF(Parameters!I24 ="NY","",IF(Parameters!I24="YN", Parameters!A24&" - "&Parameters!G24, IF(Parameters!I24="YY", "","")))) -> Financials A/R - ???? | K16: =IF(Parameters!I24="NN",0,IF(Parameters!I24 ="NY",0,IF(Parameters!I24="YN", 'Service Costs'!G15, IF(Parameters!I24="YY", 0,0)))) -> 20 | L16: =IF(Parameters!I24="NN","",IF(Parameters!I24 ="NY","",IF(Parameters!I24="YN", "", IF(Parameters!I24="YY", Parameters!A24&" - "&Parameters!G24,"")))) | M16: =IF(Parameters!I24="NN",0,IF(Parameters!I24 ="NY",0,IF(Parameters!I24="YN", 0, IF(Parameters!I24="YY", 'Service Costs'!G15,0)))) -> 0
A17: =IF(Parameters!B25="Y", Parameters!A25&Parameters!G25, "") -> Bi-Directional - ???? | F17: =IF(Parameters!B25="Y", Parameters!A25&Parameters!G25, "") -> Bi-Directional - ???? | G17: ='Service Costs'!C16 -> 8 | J17: =IF(Parameters!I25="NN","",IF(Parameters!I25 ="NY","",IF(Parameters!I25="YN", Parameters!A25&" - "&Parameters!G25, IF(Parameters!I25="YY", "","")))) -> Bi-Directional - - ???? | K17: =IF(Parameters!I25="NN",0,IF(Parameters!I25 ="NY",0,IF(Parameters!I25="YN", 'Service Costs'!G16, IF(Parameters!I25="YY", 0,0)))) -> 24 | L17: =IF(Parameters!I25="NN","",IF(Parameters!I25 ="NY","",IF(Parameters!I25="YN", "", IF(Parameters!I25="YY", Parameters!A25&" - "&Parameters!G25,"")))) | M17: =IF(Parameters!I25="NN",0,IF(Parameters!I25 ="NY",0,IF(Parameters!I25="YN", 0, IF(Parameters!I25="YY", 'Service Costs'!G16,0)))) -> 0
A18: =IF(Parameters!B26="Y", Parameters!A26&Parameters!G26, "") -> Bi-Directional - ???? | F18: =IF(Parameters!B26="Y", Parameters!A26&Parameters!G26, "") -> Bi-Directional - ???? | G18: ='Service Costs'!C17 -> 24 | J18: =IF(Parameters!I26="NN","",IF(Parameters!I26 ="NY","",IF(Parameters!I26="YN", Parameters!A26&" - "&Parameters!G26, IF(Parameters!I26="YY", "","")))) | K18: =IF(Parameters!I26="NN",0,IF(Parameters!I26 ="NY",0,IF(Parameters!I26="YN", 'Service Costs'!G17, IF(Parameters!I26="YY", 0,0)))) -> 0 | L18: =IF(Parameters!I26="NN","",IF(Parameters!I26 ="NY","",IF(Parameters!I26="YN", "", IF(Parameters!I26="YY", Parameters!A26&" - "&Parameters!G26,"")))) -> Bi-Directional - - ???? | M18: =IF(Parameters!I26="NN",0,IF(Parameters!I26 ="NY",0,IF(Parameters!I26="YN", 0, IF(Parameters!I26="YY", 'Service Costs'!G17,0)))) -> 100
A19: =IF(Parameters!B27="Y", Parameters!A27&Parameters!G27, "") | F19: =IF(Parameters!B27="Y", Parameters!A27&Parameters!G27, "") | G19: ='Service Costs'!C18 -> 0 | J19: =IF(Parameters!I27="NN","",IF(Parameters!I27 ="NY","",IF(Parameters!I27="YN", Parameters!A27&" - "&Parameters!G27, IF(Parameters!I27="YY", "","")))) | K19: =IF(Parameters!I27="NN",0,IF(Parameters!I27 ="NY",0,IF(Parameters!I27="YN", 'Service Costs'!G18, IF(Parameters!I27="YY", 0,0)))) -> 0 | L19: =IF(Parameters!I27="NN","",IF(Parameters!I27 ="NY","",IF(Parameters!I27="YN", "", IF(Parameters!I27="YY", Parameters!A27&" - "&Parameters!G27,"")))) | M19: =IF(Parameters!I27="NN",0,IF(Parameters!I27 ="NY",0,IF(Parameters!I27="YN", 0, IF(Parameters!I27="YY", 'Service Costs'!G18,0)))) -> 0
A20: =IF(Parameters!B28="Y", Parameters!A28&Parameters!G28, "") | F20: =IF(Parameters!B28="Y", Parameters!A28&Parameters!G28, "") | G20: ='Service Costs'!C19 -> 0 | J20: =IF(Parameters!I28="NN","",IF(Parameters!I28 ="NY","",IF(Parameters!I28="YN", Parameters!A28&" - "&Parameters!G28, IF(Parameters!I28="YY", "","")))) | K20: =IF(Parameters!I28="NN",0,IF(Parameters!I28 ="NY",0,IF(Parameters!I28="YN", 'Service Costs'!G19, IF(Parameters!I28="YY", 0,0)))) -> 0 | L20: =IF(Parameters!I28="NN","",IF(Parameters!I28 ="NY","",IF(Parameters!I28="YN", "", IF(Parameters!I28="YY", Parameters!A28&" - "&Parameters!G28,"")))) | M20: =IF(Parameters!I28="NN",0,IF(Parameters!I28 ="NY",0,IF(Parameters!I28="YN", 0, IF(Parameters!I28="YY", 'Service Costs'!G19,0)))) -> 0
A21: =IF(Parameters!B34="Y", Parameters!A34&Parameters!G34, "") | F21: =IF(Parameters!B34="Y", Parameters!A34&Parameters!G34, "") | G21: ='Service Costs'!C20 -> 0 | J21: =IF(Parameters!I34="NN","",IF(Parameters!I34 ="NY","",IF(Parameters!I34="YN", Parameters!A34&" - "&Parameters!G34, IF(Parameters!I34="YY", "","")))) | K21: =IF(Parameters!I34="NN",0,IF(Parameters!I34 ="NY",0,IF(Parameters!I34="YN", 'Service Costs'!G20, IF(Parameters!I34="YY", 0,0)))) -> 0 | L21: =IF(Parameters!I34="NN","",IF(Parameters!I34 ="NY","",IF(Parameters!I34="YN", "", IF(Parameters!I34="YY", Parameters!A34&" - "&Parameters!G34,"")))) | M21: =IF(Parameters!I34="NN",0,IF(Parameters!I34 ="NY",0,IF(Parameters!I34="YN", 0, IF(Parameters!I34="YY", 'Service Costs'!G20,0)))) -> 0
A22: =IF(Parameters!B45="Y", Parameters!A45&Parameters!G45, "") -> Payment Import - ???? | F22: =IF(Parameters!B45="Y", Parameters!A45&Parameters!G45, "") -> Payment Import - ???? | G22: ='Service Costs'!C31 -> 8 | J22: =IF(Parameters!B45="Y", Parameters!A45&Parameters!G45, "") -> Payment Import - ???? | K22: ='Service Costs'!G31 -> 16
A23: =IF(Parameters!B46="Y", Parameters!A46&Parameters!G46, "") -> Payment Import - ???? | F23: =IF(Parameters!B46="Y", Parameters!A46&Parameters!G46, "") -> Payment Import - ???? | G23: ='Service Costs'!C32 -> 8 | J23: =IF(Parameters!B46="Y", Parameters!A46&Parameters!G46, "") -> Payment Import - ???? | K23: ='Service Costs'!G32 -> 16
A24: =IF(Parameters!B47="Y", Parameters!A47&Parameters!G47, "") | F24: =IF(Parameters!B47="Y", Parameters!A47&Parameters!G47, "") | G24: ='Service Costs'!C33 -> 0 | J24: =IF(Parameters!B47="Y", Parameters!A47&Parameters!G47, "") | K24: ='Service Costs'!G33 -> 0
A25: =IF(Parameters!B48="Y", Parameters!A48&Parameters!G48, "") | F25: =IF(Parameters!B48="Y", Parameters!A48&Parameters!G48, "") | G25: ='Service Costs'!C34 -> 0 | J25: =IF(Parameters!B48="Y", Parameters!A48&Parameters!G48, "") | K25: ='Service Costs'!G34 -> 0
A26: =IF(Parameters!B49="Y", Parameters!A49&Parameters!G49, "") | F26: =IF(Parameters!B49="Y", Parameters!A49&Parameters!G49, "") | G26: ='Service Costs'!C35 -> 0 | J26: =IF(Parameters!B49="Y", Parameters!A49&Parameters!G49, "") | K26: ='Service Costs'!G35 -> 0
A27: =IF(Parameters!B50="Y", Parameters!A50&Parameters!G50, "") | F27: =IF(Parameters!B50="Y", Parameters!A50&Parameters!G50, "") | G27: ='Service Costs'!C36 -> 0 | J27: =IF(Parameters!B50="Y", Parameters!A50&Parameters!G50, "") | K27: ='Service Costs'!G36 -> 0
A28: =IF(Parameters!B51="Y", Parameters!A51&Parameters!G51, "") | F28: =IF(Parameters!B51="Y", Parameters!A51&Parameters!G51, "") | G28: ='Service Costs'!C37 -> 0 | J28: =IF(Parameters!B51="Y", Parameters!A51&Parameters!G51, "") | K28: ='Service Costs'!G37 -> 0
A29: =IF(Parameters!B52="Y", Parameters!A52&Parameters!G52, "") | F29: =IF(Parameters!B52="Y", Parameters!A52&Parameters!G52, "") | G29: ='Service Costs'!C38 -> 0 | J29: =IF(Parameters!B52="Y", Parameters!A52&Parameters!G52, "") | K29: ='Service Costs'!G38 -> 0
A30: ='Service Costs'!A46 -> Misc - 1 | F30: ='Service Costs'!A46 -> Misc - 1 | G30: ='Service Costs'!C46 -> 0 | L30: ='Service Costs'!A46 -> Misc - 1 | M30: ='Service Costs'!G46 -> 0
A31: ='Service Costs'!A47 -> Misc - 2 | F31: ='Service Costs'!A47 -> Misc - 2 | G31: ='Service Costs'!C47 -> 0 | L31: ='Service Costs'!A47 -> Misc - 2 | M31: ='Service Costs'!G47 -> 0
A32: ='Service Costs'!A48 -> Misc - 3 | F32: ='Service Costs'!A48 -> Misc - 3 | G32: ='Service Costs'!C48 -> 0 | L32: ='Service Costs'!A48 -> Misc - 3 | M32: ='Service Costs'!G48 -> 0
B33: Planning | H33: Implementation | P33: Training/UAT/Go-Live | X33: PM | Z33: Travel
C34: Percentage | E34: Percentage | G34: Percentage | I34: Percentage | K34: Percentage | M34: Percentage | O34: Percentage | Q34: Percentage | U34: Percentage | W34: Percentage | Y34: Percentage | AA34: Percentage
B35: Planning Configurator Percentage | C35: 0.95 | D35: Planning Technical Configurator | E35: 1 | F35: Planning BA Percentage | G35: 1 | H35: Configurator | I35: 0.9 | J35: Technical Configurator | K35: 0.9 | L35: Interface Development | M35: 0.9 | N35: Product Development | O35: 0.8 | P35: Trainer | Q35: 0.6 | R35: Trainer | S35: 1 | T35: UAT/GoLive Configurator | U35: 0.4 | V35: UAT/GoLive Product Developer | W35: 0.2 | X35: Project Manger | Y35: 0.7 | Z35: Configurator | AA35: 0.25
B36: Planning OPS Dev Environment Percentage | C36: 0.05 | H36: OPS Test and Prod Environment Percentage | I36: 0.1 | J36: OPS Test and Prod Environment Percentage | K36: 0.1 | L36: Inteface QA | M36: 0.1 | N36: Product QA | O36: 0.2 | P36: SIT QA | Q36: 0.4 | T36: UAT/GoLive Technical Configurator | U36: 0.4 | X36: Project Administrator | Y36: 0.3 | Z36: Technical Configurator | AA36: 0.25
T37: UAT/GoLive Project Developer | U37: 0.2 | Z37: BA | AA37: 0.25
Z38: Trainer | AA38: 0.25
B45: Configurator Hours | C45: {=SUM((C35*(C6:C15)),(I35*(I6:I13)),(U35*(U6:U9)),(AA35*(AA6)))} -> #REF!
B46: Technical Configuration Hours | C46: {=SUM((E35*(E6:E19)),(K35*(K6:K31)),(U36*(U6:U9)),(AA36*(AA6)))} -> #REF!
B47: BA Hours | C47: {=SUM((G35*(G6:G32)),(AA37*(AA6)))} -> 66
B48: PM Hours | C48: =SUM(Y35*Y6) -> 63
B49: PMA Hours | C49: =SUM(Y36*Y6) -> 27
B50: Project Development Hours | C50: {=SUM((M35*(M6:M31)),(U37*(U6:U9)))} -> 114
...

Sheet Travel Costs
A1: ="Travel Calculations - "&Parameters!G3 -> Travel Calculations - TELLER CLIENT, STATE
B3: Estimated hours | C3: Pricing hours | D3: Est. Number of Days | E3: Pricing Number of Days | F3: Est. Number of Staff | G3: Pricing Number of Staff | I3: Standard Travel Time | J3: Airfare | K3: Rental | L3: Per Diem Expense | M3: Est. Travel Expense | N3: Price Travel Expense
A5: Training Activity
A7: Project Kickoff and Analysis | B7: =VariablesandTravel!$C27 -> 16 | C7: =B7 -> 16 | D7: =C7/8 -> 2 | E7: =C7/8 -> 2 | F7: =VariablesandTravel!$E27 -> 2 | G7: =F7 -> 2 | I7: =VariablesandTravel!$C$5*G7 -> 1840 | J7: =VariablesandTravel!$C$15*G7 -> 1700 | K7: =IF(B7>0, (VariablesandTravel!$C$20*(E7+1)), 0) -> 375 | L7: =SUM(VariablesandTravel!$C$18, VariablesandTravel!$C$19, VariablesandTravel!$C$21) * (E7 + 1) * G7 -> 1590 | M7: =SUM(J7+K7+L7) -> 3665 | N7: =M7 -> 3665
A8: Interface Integration and Analysis | B8: =IF(Parameters_BidirectionalInterfaceCount>2, VariablesandTravel!$C31, 0) -> 16 | C8: =B8 -> 16 | D8: =C8/8 -> 2 | E8: =C8/8 -> 2 | F8: =IF(Parameters_BidirectionalInterfaceCount > 2, VariablesandTravel!$E31, 0) -> 1 | G8: =F8 -> 1 | I8: =VariablesandTravel!$C$5*G8 -> 920 | J8: =VariablesandTravel!$C$15*G8 -> 850 | K8: =IF(B8>0, (VariablesandTravel!$C$20*(E8+1)), 0) -> 375 | L8: =SUM(VariablesandTravel!$C$18, VariablesandTravel!$C$19, VariablesandTravel!$C$21) * (E8 + 1) * G8 -> 795 | M8: =SUM(J8+K8+L8) -> 2020 | N8: =M8 -> 2020
A9: Training | B9: =VariablesandTravel!$C35 -> 16 | C9: =B9 -> 16 | D9: =C9/8 -> 2 | E9: =C9/8 -> 2 | F9: =VariablesandTravel!$E35 -> 2 | G9: =F9 -> 2 | I9: =VariablesandTravel!$C$5*G9 -> 1840 | J9: =VariablesandTravel!$C$15*G9 -> 1700 | K9: =IF(B9>0, (VariablesandTravel!$C$20*(E9+1)), 0) -> 375 | L9: =SUM(VariablesandTravel!$C$18, VariablesandTravel!$C$19, VariablesandTravel!$C$21) * (E9 + 1) * G9 -> 1590 | M9: =SUM(J9+K9+L9) -> 3665 | N9: =M9 -> 3665
A10: Go Live Support | B10: =VariablesandTravel!$C39 -> 16 | C10: =B10 -> 16 | D10: =C10/8 -> 2 | E10: =D10 -> 2 | F10: =VariablesandTravel!$E39 -> 1 | G10: =F10 -> 1 | I10: =VariablesandTravel!$C$5*G10 -> 920 | J10: =VariablesandTravel!$C$15*G10 -> 850 | K10: =IF(B10>0, (VariablesandTravel!$C$20*(E10+1)), 0) -> 375 | L10: =SUM(VariablesandTravel!$C$18, VariablesandTravel!$C$19, VariablesandTravel!$C$21) * (E10 + 1) * G10 -> 795 | M10: =SUM(J10+K10+L10) -> 2020 | N10: =M10 -> 2020
A11: Other
A13: Total: | B13: =SUM(B6:B12) -> 64 | C13: =SUM(C6:C12) -> 64 | D13: =SUM(D6:D12) -> 8 | E13: =SUM(E6:E12) -> 8 | F13: =SUM(F6:F12) -> 6 | G13: =SUM(G6:G12) -> 6 | I13: =SUM(I6:I12) -> 5520 | J13: =SUM(J6:J12) -> 5100 | K13: =SUM(K6:K12) -> 1500 | L13: =SUM(L6:L12) -> 4770 | M13: =SUM(M6:M12) -> 11370 | N13: =SUM(N6:N12) -> 11370

Sheet Equipment Breakdown
A1: =Parameters!G3 -> TELLER CLIENT, STATE
A2: Equipment Calculations
A4: Item/Component | B4: Model/Description | C4: Unit Price | D4: Quantity | F4: Extended Price
A6: Receipt Printer | B6: Epson TM-M30III/USB/Thermal Printer | C6: 312 | D6: 0 | F6: =IF(D6>0,(C6*D6),0) -> 0
A7: Receipt Printer | C7: 0 | D7: 0 | F7: =IF(D7>0,(C7*D7),0) -> 0
A9: Check Scanner - single check | B9: Digital Check CheXpress CX30-IJ | C9: 523 | D9: 0 | F9: =IF(D9>0,(C9*D9),0) -> 0
A10: Check Scanner | C10: 0 | D10: 0 | F10: =IF(D10>0,(C10*D10),0) -> 0
A12: Check Scanner - bulk scanning | B12: Digital Check TS 240 | C12: 1175 | D12: 0 | F12: =IF(D12>0,(C12*D12),0) -> 0
A13: Check Scanner | C13: 0 | D13: 0 | F13: =IF(D13>0,(C13*D13),0) -> 0
A15: Cash Drawer | B15: APG Series 4000 Electronic Cash Drawer with Multi-Pro interface cable | C15: 406 | D15: 0 | F15: =IF(D15>0,(C15*D15),0) -> 0
A16: Cash Drawer | C16: 0 | D16: 0 | F16: =IF(D16>0,(C16*D16),0) -> 0
A18: Credit/Debit Device | B18: Ingenico Lane 7000 USB credit/debit PINPad with cables | C18: 786 | D18: 0 | F18: =IF(D18>0,(C18*D18),0) -> 0
A20: Cash Counter | B20: Cassida Zeus Cash Counter | C20: 2912 | D20: 0 | F20: =IF(D20>0,(C20*D20),0) -> 0
A22: Total Equipment | D22: =SUM(D6:D19) -> 0 | F22: =SUM(F6:F21) -> 0
A25: NOTE- Build in Shipping Option
A27: HONEYWELL, MS9540 VOYAGER CG KIT, SCANNER, LIGHT GRAY, USB, WITH STAND

Sheet Variables-Software
A1: ="Variables Software - "&Parameters!G3 -> Variables Software - TELLER CLIENT, STATE
A2: Software-Base | B2: Units | C2: Monthly Price | D2: Notes
A3: Teller Standard | B3: 1 | C3: 2950 | D3: Includes 5 users and is for multi-department implementations
A4: Teller Basic | B4: 1 | C4: 995 | D4: Includes 5 users
A5: Additional Users < 45 | B5: 1 | C5: 60
A6: Additional Users 45+ | B6: 1 | C6: 60 | D6: If over 50 users, check on lower per user fee
A8: Software-Applications | E8: Price per scan
A9: Check Recognition/Bulk Scanning | B9: 0 | C9: 170 | D9: Based on number of annual scans | E9: =C9/B10 -> 0.011332578
B10: 15001 | C10: 340 | E10: =C10/B11 -> 0.011332956
B11: 30001 | C11: 680 | E11: =C11/B12 -> 0.011333144
